<sdf version='1.9'>
  <model name='minidog'>
    <link name='base_footprint'>
      <inertial>
        <pose>0.006250000000000001 0 0.09437500000000001 0 0 0</pose>
        <mass>3.2000000000000002</mass>
        <inertia>
          <ixx>0.01260541666666665</ixx>
          <ixy>0</ixy>
          <ixz>-0.0013125000000000001</ixz>
          <iyy>0.02698374999999999</iyy>
          <iyz>0</iyz>
          <izz>0.034461666666666668</izz>
        </inertia>
      </inertial>
      <collision name='base_footprint_fixed_joint_lump__base_link_collision'>
        <pose>0 0 0.09 0 0 0</pose>
        <geometry>
          <box>
            <size>0.3 0.2 0.08</size>
          </box>
        </geometry>
      </collision>
      <collision name='base_footprint_fixed_joint_lump__lidar_link_collision_1'>
        <pose>0.1 0 0.16 0 0 0</pose>
        <geometry>
          <cylinder>
            <length>0.050000000000000003</length>
            <radius>0.029999999999999999</radius>
          </cylinder>
        </geometry>
        <surface>
          <contact>
            <ode/>
          </contact>
          <friction>
            <ode/>
          </friction>
        </surface>
      </collision>
      <visual name='base_footprint_fixed_joint_lump__base_link_visual'>
        <pose>0 0 0.09 0 0 0</pose>
        <geometry>
          <box>
            <size>0.3 0.2 0.08</size>
          </box>
        </geometry>
        <material>
          <diffuse>0.75 0.75 0.75 1</diffuse>
          <ambient>0.75 0.75 0.75 1</ambient>
        </material>
      </visual>
      <visual name='base_footprint_fixed_joint_lump__lidar_link_visual_1'>
        <pose>0.1 0 0.16 0 0 0</pose>
        <geometry>
          <cylinder>
            <length>0.050000000000000003</length>
            <radius>0.029999999999999999</radius>
          </cylinder>
        </geometry>
        <material>
          <diffuse>0.25 0.25 0.25 1</diffuse>
          <ambient>0.25 0.25 0.25 1</ambient>
        </material>
      </visual>
      <sensor name='ouster' type='gpu_lidar'>
        <topic>/minidog/ouster/points</topic>
        <update_rate>10</update_rate>
        <lidar>
          <scan>
            <horizontal>
              <samples>1024</samples>
              <resolution>1</resolution>
              <min_angle>-3.1415899999999999</min_angle>
              <max_angle>3.1415899999999999</max_angle>
            </horizontal>
            <vertical>
              <samples>32</samples>
              <resolution>1</resolution>
              <min_angle>-0.261799</min_angle>
              <max_angle>0.261799</max_angle>
            </vertical>
          </scan>
          <range>
            <min>0.10000000000000001</min>
            <max>20</max>
            <resolution>0.01</resolution>
          </range>
        </lidar>
        <visualize>true</visualize>
        <pose>0.1 0 0.16 0 -0 0</pose>
        <alwaysOn>1</alwaysOn>
      </sensor>
    </link>
    <joint name='front_left_steer_joint' type='revolute'>
      <pose relative_to='base_footprint'>0.11 0.09 0.05 0 0 0</pose>
      <parent>base_footprint</parent>
      <child>front_left_steer_link</child>
      <axis>
        <xyz>0 0 1</xyz>
        <limit>
          <lower>-0.59999999999999998</lower>
          <upper>0.59999999999999998</upper>
          <effort>5</effort>
          <velocity>2</velocity>
        </limit>
        <dynamics>
          <spring_reference>0</spring_reference>
          <spring_stiffness>0</spring_stiffness>
        </dynamics>
      </axis>
    </joint>
    <link name='front_left_steer_link'>
      <pose relative_to='front_left_steer_joint'>0 0 0 0 0 0</pose>
      <inertial>
        <pose>0 0 0 0 0 0</pose>
        <mass>0.050000000000000003</mass>
        <inertia>
          <ixx>3.3333333333333329e-06</ixx>
          <ixy>0</ixy>
          <ixz>0</ixz>
          <iyy>3.3333333333333329e-06</iyy>
          <iyz>0</iyz>
          <izz>3.3333333333333329e-06</izz>
        </inertia>
      </inertial>
      <collision name='front_left_steer_link_collision'>
        <pose>0 0 0 0 0 0</pose>
        <geometry>
          <box>
            <size>0.02 0.02 0.02</size>
          </box>
        </geometry>
      </collision>
      <visual name='front_left_steer_link_visual'>
        <pose>0 0 0 0 0 0</pose>
        <geometry>
          <box>
            <size>0.02 0.02 0.02</size>
          </box>
        </geometry>
        <material>
          <diffuse>0.25 0.25 1 1</diffuse>
          <ambient>0.25 0.25 1 1</ambient>
        </material>
      </visual>
    </link>
    <joint name='front_left_wheel_joint' type='revolute'>
      <pose relative_to='front_left_steer_link'>0 0 0 0 0 0</pose>
      <parent>front_left_steer_link</parent>
      <child>front_left_wheel_link</child>
      <axis>
        <xyz>0 1 0</xyz>
        <limit>
          <lower>-10000000000000000</lower>
          <upper>10000000000000000</upper>
        </limit>
        <dynamics>
          <spring_reference>0</spring_reference>
          <spring_stiffness>0</spring_stiffness>
        </dynamics>
      </axis>
    </joint>
    <link name='front_left_wheel_link'>
      <pose relative_to='front_left_wheel_joint'>0 0 0 0 0 0</pose>
      <inertial>
        <pose>0 0 0 0 0 0</pose>
        <mass>0.25</mass>
        <inertia>
          <ixx>0.00016458333333333331</ixx>
          <ixy>0</ixy>
          <ixz>0</ixz>
          <iyy>0.00031250000000000011</iyy>
          <iyz>0</iyz>
          <izz>0.00016458333333333331</izz>
        </inertia>
      </inertial>
      <collision name='front_left_wheel_link_collision'>
        <pose>0 0 0 1.570796326794896 0 0</pose>
        <geometry>
          <cylinder>
            <length>0.02</length>
            <radius>0.050000000000000003</radius>
          </cylinder>
        </geometry>
      </collision>
      <visual name='front_left_wheel_link_visual'>
        <pose>0 0 0 1.570796326794896 0 0</pose>
        <geometry>
          <cylinder>
            <length>0.02</length>
            <radius>0.050000000000000003</radius>
          </cylinder>
        </geometry>
        <material>
          <diffuse>0.125 0.125 0.125 1</diffuse>
          <ambient>0.125 0.125 0.125 1</ambient>
        </material>
      </visual>
    </link>
    <joint name='front_right_steer_joint' type='revolute'>
      <pose relative_to='base_footprint'>0.11 -0.09 0.05 0 0 0</pose>
      <parent>base_footprint</parent>
      <child>front_right_steer_link</child>
      <axis>
        <xyz>0 0 1</xyz>
        <limit>
          <lower>-0.59999999999999998</lower>
          <upper>0.59999999999999998</upper>
          <effort>5</effort>
          <velocity>2</velocity>
        </limit>
        <dynamics>
          <spring_reference>0</spring_reference>
          <spring_stiffness>0</spring_stiffness>
        </dynamics>
      </axis>
    </joint>
    <link name='front_right_steer_link'>
      <pose relative_to='front_right_steer_joint'>0 0 0 0 0 0</pose>
      <inertial>
        <pose>0 0 0 0 0 0</pose>
        <mass>0.050000000000000003</mass>
        <inertia>
          <ixx>3.3333333333333329e-06</ixx>
          <ixy>0</ixy>
          <ixz>0</ixz>
          <iyy>3.3333333333333329e-06</iyy>
          <iyz>0</iyz>
          <izz>3.3333333333333329e-06</izz>
        </inertia>
      </inertial>
      <collision name='front_right_steer_link_collision'>
        <pose>0 0 0 0 0 0</pose>
        <geometry>
          <box>
            <size>0.02 0.02 0.02</size>
          </box>
        </geometry>
      </collision>
      <visual name='front_right_steer_link_visual'>
        <pose>0 0 0 0 0 0</pose>
        <geometry>
          <box>
            <size>0.02 0.02 0.02</size>
          </box>
        </geometry>
        <material>
          <diffuse>0.25 0.25 1 1</diffuse>
          <ambient>0.25 0.25 1 1</ambient>
        </material>
      </visual>
    </link>
    <joint name='front_right_wheel_joint' type='revolute'>
      <pose relative_to='front_right_steer_link'>0 0 0 0 0 0</pose>
      <parent>front_right_steer_link</parent>
      <child>front_right_wheel_link</child>
      <axis>
        <xyz>0 1 0</xyz>
        <limit>
          <lower>-10000000000000000</lower>
          <upper>10000000000000000</upper>
        </limit>
        <dynamics>
          <spring_reference>0</spring_reference>
          <spring_stiffness>0</spring_stiffness>
        </dynamics>
      </axis>
    </joint>
    <link name='front_right_wheel_link'>
      <pose relative_to='front_right_wheel_joint'>0 0 0 0 0 0</pose>
      <inertial>
        <pose>0 0 0 0 0 0</pose>
        <mass>0.25</mass>
        <inertia>
          <ixx>0.00016458333333333331</ixx>
          <ixy>0</ixy>
          <ixz>0</ixz>
          <iyy>0.00031250000000000011</iyy>
          <iyz>0</iyz>
          <izz>0.00016458333333333331</izz>
        </inertia>
      </inertial>
      <collision name='front_right_wheel_link_collision'>
        <pose>0 0 0 1.570796326794896 0 0</pose>
        <geometry>
          <cylinder>
            <length>0.02</length>
            <radius>0.050000000000000003</radius>
          </cylinder>
        </geometry>
      </collision>
      <visual name='front_right_wheel_link_visual'>
        <pose>0 0 0 1.570796326794896 0 0</pose>
        <geometry>
          <cylinder>
            <length>0.02</length>
            <radius>0.050000000000000003</radius>
          </cylinder>
        </geometry>
        <material>
          <diffuse>0.125 0.125 0.125 1</diffuse>
          <ambient>0.125 0.125 0.125 1</ambient>
        </material>
      </visual>
    </link>
    <joint name='rear_left_wheel_joint' type='revolute'>
      <pose relative_to='base_footprint'>-0.11 0.09 0.05 0 0 0</pose>
      <parent>base_footprint</parent>
      <child>rear_left_wheel_link</child>
      <axis>
        <xyz>0 1 0</xyz>
        <limit>
          <lower>-10000000000000000</lower>
          <upper>10000000000000000</upper>
        </limit>
        <dynamics>
          <spring_reference>0</spring_reference>
          <spring_stiffness>0</spring_stiffness>
        </dynamics>
      </axis>
    </joint>
    <link name='rear_left_wheel_link'>
      <pose relative_to='rear_left_wheel_joint'>0 0 0 0 0 0</pose>
      <inertial>
        <pose>0 0 0 0 0 0</pose>
        <mass>0.25</mass>
        <inertia>
          <ixx>0.00016458333333333331</ixx>
          <ixy>0</ixy>
          <ixz>0</ixz>
          <iyy>0.00031250000000000011</iyy>
          <iyz>0</iyz>
          <izz>0.00016458333333333331</izz>
        </inertia>
      </inertial>
      <collision name='rear_left_wheel_link_collision'>
        <pose>0 0 0 1.570796326794896 0 0</pose>
        <geometry>
          <cylinder>
            <length>0.02</length>
            <radius>0.050000000000000003</radius>
          </cylinder>
        </geometry>
      </collision>
      <visual name='rear_left_wheel_link_visual'>
        <pose>0 0 0 1.570796326794896 0 0</pose>
        <geometry>
          <cylinder>
            <length>0.02</length>
            <radius>0.050000000000000003</radius>
          </cylinder>
        </geometry>
        <material>
          <diffuse>0.125 0.125 0.125 1</diffuse>
          <ambient>0.125 0.125 0.125 1</ambient>
        </material>
      </visual>
    </link>
    <joint name='rear_right_wheel_joint' type='revolute'>
      <pose relative_to='base_footprint'>-0.11 -0.09 0.05 0 0 0</pose>
      <parent>base_footprint</parent>
      <child>rear_right_wheel_link</child>
      <axis>
        <xyz>0 1 0</xyz>
        <limit>
          <lower>-10000000000000000</lower>
          <upper>10000000000000000</upper>
        </limit>
        <dynamics>
          <spring_reference>0</spring_reference>
          <spring_stiffness>0</spring_stiffness>
        </dynamics>
      </axis>
    </joint>
    <link name='rear_right_wheel_link'>
      <pose relative_to='rear_right_wheel_joint'>0 0 0 0 0 0</pose>
      <inertial>
        <pose>0 0 0 0 0 0</pose>
        <mass>0.25</mass>
        <inertia>
          <ixx>0.00016458333333333331</ixx>
          <ixy>0</ixy>
          <ixz>0</ixz>
          <iyy>0.00031250000000000011</iyy>
          <iyz>0</iyz>
          <izz>0.00016458333333333331</izz>
        </inertia>
      </inertial>
      <collision name='rear_right_wheel_link_collision'>
        <pose>0 0 0 1.570796326794896 0 0</pose>
        <geometry>
          <cylinder>
            <length>0.02</length>
            <radius>0.050000000000000003</radius>
          </cylinder>
        </geometry>
      </collision>
      <visual name='rear_right_wheel_link_visual'>
        <pose>0 0 0 1.570796326794896 0 0</pose>
        <geometry>
          <cylinder>
            <length>0.02</length>
            <radius>0.050000000000000003</radius>
          </cylinder>
        </geometry>
        <material>
          <diffuse>0.125 0.125 0.125 1</diffuse>
          <ambient>0.125 0.125 0.125 1</ambient>
        </material>
      </visual>
    </link>
    <plugin name='gz::sim::systems::AckermannSteering' filename='ignition-gazebo-ackermann-steering-system'>
      <left_joint>rear_left_wheel_joint</left_joint>
      <right_joint>rear_right_wheel_joint</right_joint>
      <left_steering_joint>front_left_steer_joint</left_steering_joint>
      <right_steering_joint>front_right_steer_joint</right_steering_joint>
      <kingpin_width>0.18</kingpin_width>
      <steering_limit>0.6</steering_limit>
      <wheel_base>0.22</wheel_base>
      <wheel_separation>0.18</wheel_separation>
      <wheel_radius>0.05</wheel_radius>
      <min_velocity>-2</min_velocity>
      <max_velocity>2</max_velocity>
      <min_acceleration>-3</min_acceleration>
      <max_acceleration>3</max_acceleration>
    </plugin>
    <plugin name='gz::sim::systems::JointStatePublisher' filename='ignition-gazebo-joint-state-publisher-system'/>
    <plugin name='ignition::gazebo::systems::OdometryPublisher' filename='ignition-gazebo-odometry-publisher-system'>
      <dimensions>3</dimensions>
      <odom_frame>odom</odom_frame>
      <robot_base_frame>base_footprint</robot_base_frame>
      <odom_publish_frequency>50</odom_publish_frequency>
    </plugin>
    <frame name='lidar_joint' attached_to='base_link'>
      <pose>0.1 0 0.07 0 -0 0</pose>
    </frame>
    <frame name='lidar_link' attached_to='lidar_joint'/>
    <frame name='base_footprint_joint' attached_to='base_footprint'>
      <pose>0 0 0.09 0 -0 0</pose>
    </frame>
    <frame name='base_link' attached_to='base_footprint_joint'/>
  </model>
</sdf>
